[2022-07-17 14:20:00,675] {taskinstance.py:1179} INFO - Dependencies all met for <TaskInstance: attraction_taskflow_api_etl.load manual__2022-07-17T14:19:27.619037+00:00 [queued]>
[2022-07-17 14:20:00,692] {taskinstance.py:1179} INFO - Dependencies all met for <TaskInstance: attraction_taskflow_api_etl.load manual__2022-07-17T14:19:27.619037+00:00 [queued]>
[2022-07-17 14:20:00,693] {taskinstance.py:1376} INFO - 
--------------------------------------------------------------------------------
[2022-07-17 14:20:00,695] {taskinstance.py:1377} INFO - Starting attempt 1 of 1
[2022-07-17 14:20:00,696] {taskinstance.py:1378} INFO - 
--------------------------------------------------------------------------------
[2022-07-17 14:20:00,715] {taskinstance.py:1397} INFO - Executing <Task(_PythonDecoratedOperator): load> on 2022-07-17 14:19:27.619037+00:00
[2022-07-17 14:20:00,724] {standard_task_runner.py:52} INFO - Started process 42883 to run task
[2022-07-17 14:20:00,729] {standard_task_runner.py:79} INFO - Running: ['***', 'tasks', 'run', 'attraction_taskflow_api_etl', 'load', 'manual__2022-07-17T14:19:27.619037+00:00', '--job-id', '55', '--raw', '--subdir', 'DAGS_FOLDER/atrraction_api_extract.py', '--cfg-path', '/tmp/tmpubx3av6y', '--error-file', '/tmp/tmppp2ewz44']
[2022-07-17 14:20:00,734] {standard_task_runner.py:80} INFO - Job 55: Subtask load
[2022-07-17 14:20:01,040] {task_command.py:371} INFO - Running <TaskInstance: attraction_taskflow_api_etl.load manual__2022-07-17T14:19:27.619037+00:00 [running]> on host 608c485e41f3
[2022-07-17 14:20:01,439] {taskinstance.py:1591} INFO - Exporting the following env vars:
AIRFLOW_CTX_DAG_OWNER=***
AIRFLOW_CTX_DAG_ID=attraction_taskflow_api_etl
AIRFLOW_CTX_TASK_ID=load
AIRFLOW_CTX_EXECUTION_DATE=2022-07-17T14:19:27.619037+00:00
AIRFLOW_CTX_TRY_NUMBER=1
AIRFLOW_CTX_DAG_RUN_ID=manual__2022-07-17T14:19:27.619037+00:00
[2022-07-17 14:20:01,442] {logging_mixin.py:115} INFO - /opt/***/dags/credentials.json
[2022-07-17 14:20:02,216] {taskinstance.py:1909} ERROR - Task failed with exception
Traceback (most recent call last):
  File "/home/airflow/.local/lib/python3.7/site-packages/airflow/decorators/base.py", line 179, in execute
    return_value = super().execute(context)
  File "/home/airflow/.local/lib/python3.7/site-packages/airflow/operators/python.py", line 171, in execute
    return_value = self.execute_callable()
  File "/home/airflow/.local/lib/python3.7/site-packages/airflow/operators/python.py", line 189, in execute_callable
    return self.python_callable(*self.op_args, **self.op_kwargs)
  File "/opt/airflow/dags/atrraction_api_extract.py", line 108, in load
    bq_client.get_table('%s.%s.%s' % (project_id, dataset_id, table_id))
  File "/home/airflow/.local/lib/python3.7/site-packages/google/cloud/bigquery/client.py", line 1040, in get_table
    timeout=timeout,
  File "/home/airflow/.local/lib/python3.7/site-packages/google/cloud/bigquery/client.py", line 782, in _call_api
    return call()
  File "/home/airflow/.local/lib/python3.7/site-packages/google/api_core/retry.py", line 288, in retry_wrapped_func
    on_error=on_error,
  File "/home/airflow/.local/lib/python3.7/site-packages/google/api_core/retry.py", line 190, in retry_target
    return target()
  File "/home/airflow/.local/lib/python3.7/site-packages/google/cloud/_http/__init__.py", line 494, in api_request
    raise exceptions.from_http_response(response)
google.api_core.exceptions.Forbidden: 403 GET https://bigquery.googleapis.com/bigquery/v2/projects/bishare-1606/datasets/penny_test/tables/attractoins_taipei?prettyPrint=false: Access Denied: Table bishare-1606:penny_test.attractoins_taipei: Permission bigquery.tables.get denied on table bishare-1606:penny_test.attractoins_taipei (or it may not exist).
[2022-07-17 14:20:02,253] {taskinstance.py:1420} INFO - Marking task as FAILED. dag_id=attraction_taskflow_api_etl, task_id=load, execution_date=20220717T141927, start_date=20220717T142000, end_date=20220717T142002
[2022-07-17 14:20:02,270] {standard_task_runner.py:97} ERROR - Failed to execute job 55 for task load (403 GET https://bigquery.googleapis.com/bigquery/v2/projects/bishare-1606/datasets/penny_test/tables/attractoins_taipei?prettyPrint=false: Access Denied: Table bishare-1606:penny_test.attractoins_taipei: Permission bigquery.tables.get denied on table bishare-1606:penny_test.attractoins_taipei (or it may not exist).; 42883)
[2022-07-17 14:20:02,319] {local_task_job.py:156} INFO - Task exited with return code 1
[2022-07-17 14:20:02,363] {local_task_job.py:273} INFO - 0 downstream tasks scheduled from follow-on schedule check
