[2022-07-16 06:31:33,267] {taskinstance.py:1179} INFO - Dependencies all met for <TaskInstance: attraction_taskflow_api_etl.dbt_run_task manual__2022-07-16T06:30:28.200779+00:00 [queued]>
[2022-07-16 06:31:33,279] {taskinstance.py:1179} INFO - Dependencies all met for <TaskInstance: attraction_taskflow_api_etl.dbt_run_task manual__2022-07-16T06:30:28.200779+00:00 [queued]>
[2022-07-16 06:31:33,280] {taskinstance.py:1376} INFO - 
--------------------------------------------------------------------------------
[2022-07-16 06:31:33,281] {taskinstance.py:1377} INFO - Starting attempt 1 of 1
[2022-07-16 06:31:33,282] {taskinstance.py:1378} INFO - 
--------------------------------------------------------------------------------
[2022-07-16 06:31:33,297] {taskinstance.py:1397} INFO - Executing <Task(BashOperator): dbt_run_task> on 2022-07-16 06:30:28.200779+00:00
[2022-07-16 06:31:33,303] {standard_task_runner.py:52} INFO - Started process 31089 to run task
[2022-07-16 06:31:33,307] {standard_task_runner.py:79} INFO - Running: ['***', 'tasks', 'run', 'attraction_taskflow_api_etl', 'dbt_run_task', 'manual__2022-07-16T06:30:28.200779+00:00', '--job-id', '52', '--raw', '--subdir', 'DAGS_FOLDER/atrraction_api_extract.py', '--cfg-path', '/tmp/tmpmp24gvtu', '--error-file', '/tmp/tmp4cuv8ooh']
[2022-07-16 06:31:33,310] {standard_task_runner.py:80} INFO - Job 52: Subtask dbt_run_task
[2022-07-16 06:31:33,579] {task_command.py:371} INFO - Running <TaskInstance: attraction_taskflow_api_etl.dbt_run_task manual__2022-07-16T06:30:28.200779+00:00 [running]> on host 608c485e41f3
[2022-07-16 06:31:33,659] {taskinstance.py:1591} INFO - Exporting the following env vars:
AIRFLOW_CTX_DAG_OWNER=***
AIRFLOW_CTX_DAG_ID=attraction_taskflow_api_etl
AIRFLOW_CTX_TASK_ID=dbt_run_task
AIRFLOW_CTX_EXECUTION_DATE=2022-07-16T06:30:28.200779+00:00
AIRFLOW_CTX_TRY_NUMBER=1
AIRFLOW_CTX_DAG_RUN_ID=manual__2022-07-16T06:30:28.200779+00:00
[2022-07-16 06:31:33,661] {subprocess.py:62} INFO - Tmp dir root location: 
 /tmp
[2022-07-16 06:31:33,665] {subprocess.py:74} INFO - Running command: ['bash', '-c', 'dbt run']
[2022-07-16 06:31:33,694] {subprocess.py:85} INFO - Output:
[2022-07-16 06:31:33,707] {subprocess.py:92} INFO - bash: line 1: dbt: command not found
[2022-07-16 06:31:33,708] {subprocess.py:96} INFO - Command exited with return code 127
[2022-07-16 06:31:33,725] {taskinstance.py:1909} ERROR - Task failed with exception
Traceback (most recent call last):
  File "/home/airflow/.local/lib/python3.7/site-packages/airflow/operators/bash.py", line 195, in execute
    f'Bash command failed. The command returned a non-zero exit code {result.exit_code}.'
airflow.exceptions.AirflowException: Bash command failed. The command returned a non-zero exit code 127.
[2022-07-16 06:31:33,731] {taskinstance.py:1420} INFO - Marking task as FAILED. dag_id=attraction_taskflow_api_etl, task_id=dbt_run_task, execution_date=20220716T063028, start_date=20220716T063133, end_date=20220716T063133
[2022-07-16 06:31:33,747] {standard_task_runner.py:97} ERROR - Failed to execute job 52 for task dbt_run_task (Bash command failed. The command returned a non-zero exit code 127.; 31089)
[2022-07-16 06:31:33,805] {local_task_job.py:156} INFO - Task exited with return code 1
[2022-07-16 06:31:33,852] {local_task_job.py:273} INFO - 0 downstream tasks scheduled from follow-on schedule check
